<?xml version="1.0" ?>

<robot name="pizza_cutter">

<!-- Color Def - for Material blue-->
<material name = "blue">
    <color rgba = "0 0.8 1"/>
</material>

<!-- Base Link Definition-->

<link name="pizza_cutter_handle">
    <visual>
        <origin xyz="0.0 0.0 0.1" rpy="0.0 0.0 0.0"/>
        <geometry>
            <box size="0.02 0.026 0.18"/>
            <!--box size="0.13 0.026 0.02"/-->
            <!--box size="0.026 0.13 0.02"/-->
        </geometry>
    </visual>
</link>

<link name="pizza_cutter_blade">
    <visual>
        <origin xyz="0.0 0.0 0.0" rpy="0.0 0.0 0.0"/>
        <geometry>
            <cylinder radius="0.0325" length="0.005"/>
        </geometry>
        <material name="blue"/>
    </visual>
</link>

<joint name="cutting_joint" type="continuous">
    <parent link="pizza_cutter_handle"/>
    <child link="pizza_cutter_blade"/>
    <axis xyz="0 0 1"/>
    <origin xyz="-0.01 0.0 0.2" rpy="0.0 ${pi/2.0} 0.0"/>    
</joint>

</robot>
